Traceback (most recent call last):
  File "/Volumes/zorg/mb312/.virtualenvs/sp-lectures/lib/python3.12/site-packages/jupyter_core/utils/__init__.py", line 154, in wrapped
    asyncio.get_running_loop()
RuntimeError: no running event loop

During handling of the above exception, another exception occurred:

Traceback (most recent call last):
  File "/Volumes/zorg/mb312/.virtualenvs/sp-lectures/lib/python3.12/site-packages/jupyter_cache/executors/utils.py", line 58, in single_nb_execution
    executenb(
  File "/Volumes/zorg/mb312/.virtualenvs/sp-lectures/lib/python3.12/site-packages/nbclient/client.py", line 1319, in execute
    return NotebookClient(nb=nb, resources=resources, km=km, **kwargs).execute()
           ^^^^^^^^^^^^^^^^^^^^^^^^^^^^^^^^^^^^^^^^^^^^^^^^^^^^^^^^^^^^^^^^^^^^^
  File "/Volumes/zorg/mb312/.virtualenvs/sp-lectures/lib/python3.12/site-packages/jupyter_core/utils/__init__.py", line 158, in wrapped
    return loop.run_until_complete(inner)
           ^^^^^^^^^^^^^^^^^^^^^^^^^^^^^^
  File "/Library/Frameworks/Python.framework/Versions/3.12/lib/python3.12/asyncio/base_events.py", line 685, in run_until_complete
    return future.result()
           ^^^^^^^^^^^^^^^
  File "/Volumes/zorg/mb312/.virtualenvs/sp-lectures/lib/python3.12/site-packages/nbclient/client.py", line 709, in async_execute
    await self.async_execute_cell(
  File "/Volumes/zorg/mb312/.virtualenvs/sp-lectures/lib/python3.12/site-packages/nbclient/client.py", line 1062, in async_execute_cell
    await self._check_raise_for_error(cell, cell_index, exec_reply)
  File "/Volumes/zorg/mb312/.virtualenvs/sp-lectures/lib/python3.12/site-packages/nbclient/client.py", line 918, in _check_raise_for_error
    raise CellExecutionError.from_cell_and_msg(cell, exec_reply_content)
nbclient.exceptions.CellExecutionError: An error occurred while executing the following cell:
------------------
%run test.py
------------------


[31m---------------------------------------------------------------------------[39m
[31mOSError[39m                                   Traceback (most recent call last)
[36mFile [39m[32m/Volumes/zorg/mb312/.virtualenvs/sp-lectures/lib/python3.12/site-packages/IPython/core/magics/execution.py:728[39m, in [36mExecutionMagics.run[39m[34m(self, parameter_s, runner, file_finder)[39m
[32m    727[39m     fpath = arg_lst[[32m0[39m]
[32m--> [39m[32m728[39m     filename = [43mfile_finder[49m[43m([49m[43mfpath[49m[43m)[49m
[32m    729[39m [38;5;28;01mexcept[39;00m [38;5;167;01mIndexError[39;00m [38;5;28;01mas[39;00m e:

[36mFile [39m[32m/Volumes/zorg/mb312/.virtualenvs/sp-lectures/lib/python3.12/site-packages/IPython/utils/path.py:90[39m, in [36mget_py_filename[39m[34m(name)[39m
[32m     89[39m         [38;5;28;01mreturn[39;00m py_name
[32m---> [39m[32m90[39m [38;5;28;01mraise[39;00m [38;5;167;01mIOError[39;00m([33m"[39m[33mFile `[39m[38;5;132;01m%r[39;00m[33m` not found.[39m[33m"[39m % name)

[31mOSError[39m: File `'test.py'` not found.

The above exception was the direct cause of the following exception:

[31mException[39m                                 Traceback (most recent call last)
[36mCell[39m[36m [39m[32mIn[1][39m[32m, line 1[39m
[32m----> [39m[32m1[39m [43mget_ipython[49m[43m([49m[43m)[49m[43m.[49m[43mrun_line_magic[49m[43m([49m[33;43m'[39;49m[33;43mrun[39;49m[33;43m'[39;49m[43m,[49m[43m [49m[33;43m'[39;49m[33;43mtest.py[39;49m[33;43m'[39;49m[43m)[49m

[36mFile [39m[32m/Volumes/zorg/mb312/.virtualenvs/sp-lectures/lib/python3.12/site-packages/IPython/core/interactiveshell.py:2504[39m, in [36mInteractiveShell.run_line_magic[39m[34m(self, magic_name, line, _stack_depth)[39m
[32m   2502[39m     kwargs[[33m'[39m[33mlocal_ns[39m[33m'[39m] = [38;5;28mself[39m.get_local_scope(stack_depth)
[32m   2503[39m [38;5;28;01mwith[39;00m [38;5;28mself[39m.builtin_trap:
[32m-> [39m[32m2504[39m     result = [43mfn[49m[43m([49m[43m*[49m[43margs[49m[43m,[49m[43m [49m[43m*[49m[43m*[49m[43mkwargs[49m[43m)[49m
[32m   2506[39m [38;5;66;03m# The code below prevents the output from being displayed[39;00m
[32m   2507[39m [38;5;66;03m# when using magics with decorator @output_can_be_silenced[39;00m
[32m   2508[39m [38;5;66;03m# when the last Python token in the expression is a ';'.[39;00m
[32m   2509[39m [38;5;28;01mif[39;00m [38;5;28mgetattr[39m(fn, magic.MAGIC_OUTPUT_CAN_BE_SILENCED, [38;5;28;01mFalse[39;00m):

[36mFile [39m[32m/Volumes/zorg/mb312/.virtualenvs/sp-lectures/lib/python3.12/site-packages/IPython/core/magics/execution.py:739[39m, in [36mExecutionMagics.run[39m[34m(self, parameter_s, runner, file_finder)[39m
[32m    737[39m     [38;5;28;01mif[39;00m os.name == [33m'[39m[33mnt[39m[33m'[39m [38;5;129;01mand[39;00m re.match([33mr[39m[33m"[39m[33m^[39m[33m'[39m[33m.*[39m[33m'[39m[33m$[39m[33m"[39m,fpath):
[32m    738[39m         warn([33m'[39m[33mFor Windows, use double quotes to wrap a filename: [39m[38;5;132;01m%r[39;00m[33mun [39m[33m"[39m[33mmypath[39m[38;5;130;01m\\[39;00m[33mmyfile.py[39m[33m"[39m[33m'[39m)
[32m--> [39m[32m739[39m     [38;5;28;01mraise[39;00m [38;5;167;01mException[39;00m(msg) [38;5;28;01mfrom[39;00m[38;5;250m [39m[34;01me[39;00m
[32m    740[39m [38;5;28;01mexcept[39;00m [38;5;167;01mTypeError[39;00m:
[32m    741[39m     [38;5;28;01mif[39;00m fpath [38;5;129;01min[39;00m sys.meta_path:

[31mException[39m: File `'test.py'` not found.

